<?xml version="1.0"?>
<robot xmlns:xacro="http://www.ros.org/wiki/xacro">

  <xacro:include filename="$(find quadruped_robots_description)/urdf/servo_motors/servo_motors.xacro"/>

  <xacro:macro name="leg2" params="prefix parent *joint_origin">
    <joint name="${prefix}_leg2_joint" type="revolute">
      <insert_block name="joint_origin"/>
      <axis xyz="0 1 0"/>
      <KRS3302ICS_limit/>
      <parent link="${parent}"/>
      <child link="${prefix}_leg2_link"/>
    </joint>

    <link name="${prefix}_leg2_link">
      <visual>
        <geometry>
          <mesh filename="package://quadruped_robots_description/meshes/spider/leg2.STL"/>
        </geometry>
      </visual>
      <collision>
        <geometry>
          <mesh filename="package://quadruped_robots_description/meshes/spider/leg2.STL"/>
        </geometry>
      </collision>
      <inertial>
        <mass value="0.30399"/>
        <inertia ixx="0.00043265194" ixy="0.00072891592" ixz="0" iyy="0.00240300132" iyz="0" izz="0.00270222511"/>
      </inertial>
    </link>
  </xacro:macro>

</robot>
