<?xml version="1.0"?>
<robot xmlns:xacro="http://www.ros.org/wiki/xacro">

  <xacro:include filename="$(find quadruped_robots_description)/urdf/servo_motors/servo_motors.xacro"/>

  <xacro:macro name="leg3" params="prefix parent *joint_origin">
    <joint name="${prefix}_leg3_joint" type="revolute">
      <insert_block name="joint_origin"/>
      <axis xyz="0 1 0"/>
      <KRS3302ICS_limit/>
      <parent link="${parent}"/>
      <child link="${prefix}_leg3_link"/>
    </joint>

    <link name="${prefix}_leg3_link">
      <visual>
        <origin rpy="${M_PI} 0 0" xyz="0 0.06 0"/>
        <geometry>
          <mesh filename="package://quadruped_robots_description/meshes/spider/leg3.STL"/>
        </geometry>
      </visual>
      <collision>
        <origin rpy="${M_PI} 0 0" xyz="0 0.06 0"/>
        <geometry>
          <mesh filename="package://quadruped_robots_description/meshes/spider/leg3.STL"/>
        </geometry>
      </collision>
      <inertial>
        <origin rpy="${M_PI} 0 0" xyz="0 0.06 0"/>
        <mass value="0.39164"/>
        <inertia ixx="0.00057788276" ixy="0.00133144744" ixz="0.00069625346" iyy="0.00667919118" iyz="0.00012359883" izz="0.00699240886"/>
      </inertial>
    </link>
  </xacro:macro>

</robot>
